Workbook

Sheet Simple Car List
A1: Year | B1: Make | C1: Model | D1: Type | E1: Class | F1: Country
A2: ='Detailed Car List + Stats'!B2 -> 2017 | B2: ='Detailed Car List + Stats'!C2 -> Abarth | C2: ='Detailed Car List + Stats'!D2 -> 124 Spider | D2: ='Detailed Car List + Stats'!E2 -> Modern Sports Cars | E2: C | F2: ='Detailed Car List + Stats'!G2 -> Italy
A3: ='Detailed Car List + Stats'!B3 -> 1968 | B3: ='Detailed Car List + Stats'!C3 -> Abarth | C3: ='Detailed Car List + Stats'!D3 -> 595 Esseesse | D3: ='Detailed Car List + Stats'!E3 -> Cult Cars | E3: D | F3: ='Detailed Car List + Stats'!G3 -> Italy
A4: ='Detailed Car List + Stats'!B4 -> 2016 | B4: ='Detailed Car List + Stats'!C4 -> Abarth | C4: ='Detailed Car List + Stats'!D4 -> 695 Biposto | D4: ='Detailed Car List + Stats'!E4 -> Hot Hatch | E4: B | F4: ='Detailed Car List + Stats'!G4 -> Italy
A5: ='Detailed Car List + Stats'!B5 -> 1980 | B5: ='Detailed Car List + Stats'!C5 -> Abarth | C5: ='Detailed Car List + Stats'!D5 -> Fiat 131 | D5: ='Detailed Car List + Stats'!E5 -> Classic Rally | E5: D | F5: ='Detailed Car List + Stats'!G5 -> Italy
A6: ='Detailed Car List + Stats'!B6 -> 2023 | B6: ='Detailed Car List + Stats'!C6 -> Acura | C6: ='Detailed Car List + Stats'!D6 -> Integra A-Spec | D6: ='Detailed Car List + Stats'!E6 -> Hot Hatch | E6: C | F6: ='Detailed Car List + Stats'!G6 -> USA
A7: ='Detailed Car List + Stats'!B7 -> 2001 | B7: ='Detailed Car List + Stats'!C7 -> Acura | C7: ='Detailed Car List + Stats'!D7 -> Integra Type R | D7: ='Detailed Car List + Stats'!E7 -> Retro Hot Hatch | E7: C | F7: ='Detailed Car List + Stats'!G7 -> USA
A8: ='Detailed Car List + Stats'!B8 -> 2022 | B8: ='Detailed Car List + Stats'!C8 -> Acura | C8: ='Detailed Car List + Stats'!D8 -> NSX Type S | D8: ='Detailed Car List + Stats'!E8 -> Modern Supercars | E8: S1 | F8: ='Detailed Car List + Stats'!G8 -> USA
A9: ='Detailed Car List + Stats'!B9 -> 2002 | B9: ='Detailed Car List + Stats'!C9 -> Acura | C9: ='Detailed Car List + Stats'!D9 -> RSX Type S | D9: ='Detailed Car List + Stats'!E9 -> Retro Hot Hatch | E9: C | F9: ='Detailed Car List + Stats'!G9 -> USA
A10: ='Detailed Car List + Stats'!B10 -> 1992 | B10: ='Detailed Car List + Stats'!C10 -> Alfa Romeo | C10: ='Detailed Car List + Stats'!D10 -> 155 Q4 | D10: ='Detailed Car List + Stats'!E10 -> Retro Super Saloons | E10: C | F10: ='Detailed Car List + Stats'!G10 -> Italy
A11: ='Detailed Car List + Stats'!B11 -> 1968 | B11: ='Detailed Car List + Stats'!C11 -> Alfa Romeo | C11: ='Detailed Car List + Stats'!D11 -> 33 Stradale | D11: ='Detailed Car List + Stats'!E11 -> Classic Racers | E11: B | F11: ='Detailed Car List + Stats'!G11 -> Italy
A12: ='Detailed Car List + Stats'!B12 -> 2014 | B12: ='Detailed Car List + Stats'!C12 -> Alfa Romeo | C12: ='Detailed Car List + Stats'!D12 -> 4C | D12: ='Detailed Car List + Stats'!E12 -> Modern Sports Cars | E12: A | F12: ='Detailed Car List + Stats'!G12 -> Italy
A13: ='Detailed Car List + Stats'!B13 -> 2007 | B13: ='Detailed Car List + Stats'!C13 -> Alfa Romeo | C13: ='Detailed Car List + Stats'!D13 -> 8C Competizione | D13: ='Detailed Car List + Stats'!E13 -> GT Cars | E13: A | F13: ='Detailed Car List + Stats'!G13 -> Italy
... A637: ='Detailed Car List + Stats'!B637 -> 2019 | B637: ='Detailed Car List + Stats'!C637 -> Zenvo | C637: ='Detailed Car List + Stats'!D637 -> TSR-S | D637: ='Detailed Car List + Stats'!E637 -> Hypercars | E637: R | F637: ='Detailed Car List + Stats'!G637 -> Denmark

Sheet Detailed Car List
A1: Year | B1: Make | C1: Model | D1: Type | E1: Class | F1: Country | G1: Value (Cr) | H1: Rarity | I1: Source | J1: Source Info
A2: ='Detailed Car List + Stats'!B2 -> 2017 | B2: ='Detailed Car List + Stats'!C2 -> Abarth | C2: ='Detailed Car List + Stats'!D2 -> 124 Spider | D2: ='Detailed Car List + Stats'!E2 -> Modern Sports Cars | E2: C 450 | F2: ='Detailed Car List + Stats'!G2 -> Italy | G2: ='Detailed Car List + Stats'!H2 -> 250000 | H2: Rare | I2: ='Detailed Car List + Stats'!T2 -> Seasonal | J2: ='Detailed Car List + Stats'!U2
A3: ='Detailed Car List + Stats'!B3 -> 1968 | B3: ='Detailed Car List + Stats'!C3 -> Abarth | C3: ='Detailed Car List + Stats'!D3 -> 595 Esseesse | D3: ='Detailed Car List + Stats'!E3 -> Cult Cars | E3: D 100 | F3: ='Detailed Car List + Stats'!G3 -> Italy | G3: ='Detailed Car List + Stats'!H3 -> 25000 | H3: Common | I3: ='Detailed Car List + Stats'!T3 -> Autoshow, Wheelspin | J3: ='Detailed Car List + Stats'!U3
A4: ='Detailed Car List + Stats'!B4 -> 2016 | B4: ='Detailed Car List + Stats'!C4 -> Abarth | C4: ='Detailed Car List + Stats'!D4 -> 695 Biposto | D4: ='Detailed Car List + Stats'!E4 -> Hot Hatch | E4: B 540 | F4: ='Detailed Car List + Stats'!G4 -> Italy | G4: ='Detailed Car List + Stats'!H4 -> 250000 | H4: Common | I4: ='Detailed Car List + Stats'!T4 -> Seasonal | J4: ='Detailed Car List + Stats'!U4
A5: ='Detailed Car List + Stats'!B5 -> 1980 | B5: ='Detailed Car List + Stats'!C5 -> Abarth | C5: ='Detailed Car List + Stats'!D5 -> Fiat 131 | D5: ='Detailed Car List + Stats'!E5 -> Classic Rally | E5: D 399 | F5: ='Detailed Car List + Stats'!G5 -> Italy | G5: ='Detailed Car List + Stats'!H5 -> 125000 | H5: Common | I5: ='Detailed Car List + Stats'!T5 -> Autoshow, Wheelspin | J5: ='Detailed Car List + Stats'!U5
A6: ='Detailed Car List + Stats'!B6 -> 2023 | B6: ='Detailed Car List + Stats'!C6 -> Acura | C6: ='Detailed Car List + Stats'!D6 -> Integra A-Spec | D6: ='Detailed Car List + Stats'!E6 -> Hot Hatch | E6: C 484 | F6: ='Detailed Car List + Stats'!G6 -> USA | G6: ='Detailed Car List + Stats'!H6 -> 36000 | H6: Rare | I6: ='Detailed Car List + Stats'!T6 -> Autoshow, Wheelspin | J6: ='Detailed Car List + Stats'!U6
A7: ='Detailed Car List + Stats'!B7 -> 2001 | B7: ='Detailed Car List + Stats'!C7 -> Acura | C7: ='Detailed Car List + Stats'!D7 -> Integra Type R | D7: ='Detailed Car List + Stats'!E7 -> Retro Hot Hatch | E7: C 471 | F7: ='Detailed Car List + Stats'!G7 -> USA | G7: ='Detailed Car List + Stats'!H7 -> 65000 | H7: Common | I7: ='Detailed Car List + Stats'!T7 -> Autoshow, Wheelspin | J7: ='Detailed Car List + Stats'!U7
A8: ='Detailed Car List + Stats'!B8 -> 2022 | B8: ='Detailed Car List + Stats'!C8 -> Acura | C8: ='Detailed Car List + Stats'!D8 -> NSX Type S | D8: ='Detailed Car List + Stats'!E8 -> Modern Supercars | E8: S1 734 | F8: ='Detailed Car List + Stats'!G8 -> USA | G8: ='Detailed Car List + Stats'!H8 -> 193000 | H8: Epic | I8: ='Detailed Car List + Stats'!T8 -> Seasonal | J8: ='Detailed Car List + Stats'!U8
A9: ='Detailed Car List + Stats'!B9 -> 2002 | B9: ='Detailed Car List + Stats'!C9 -> Acura | C9: ='Detailed Car List + Stats'!D9 -> RSX Type S | D9: ='Detailed Car List + Stats'!E9 -> Retro Hot Hatch | E9: C 462 | F9: ='Detailed Car List + Stats'!G9 -> USA | G9: ='Detailed Car List + Stats'!H9 -> 18000 | H9: Common | I9: ='Detailed Car List + Stats'!T9 -> Autoshow, Wheelspin | J9: ='Detailed Car List + Stats'!U9
A10: ='Detailed Car List + Stats'!B10 -> 1992 | B10: ='Detailed Car List + Stats'!C10 -> Alfa Romeo | C10: ='Detailed Car List + Stats'!D10 -> 155 Q4 | D10: ='Detailed Car List + Stats'!E10 -> Retro Super Saloons | E10: C 439 | F10: ='Detailed Car List + Stats'!G10 -> Italy | G10: ='Detailed Car List + Stats'!H10 -> 30000 | H10: Epic | I10: ='Detailed Car List + Stats'!T10 -> Autoshow | J10: ='Detailed Car List + Stats'!U10
A11: ='Detailed Car List + Stats'!B11 -> 1968 | B11: ='Detailed Car List + Stats'!C11 -> Alfa Romeo | C11: ='Detailed Car List + Stats'!D11 -> 33 Stradale | D11: ='Detailed Car List + Stats'!E11 -> Classic Racers | E11: B 593 | F11: ='Detailed Car List + Stats'!G11 -> Italy | G11: ='Detailed Car List + Stats'!H11 -> 3500000 | H11: Legendary | I11: ='Detailed Car List + Stats'!T11 -> Autoshow, Wheelspin | J11: ='Detailed Car List + Stats'!U11
A12: ='Detailed Car List + Stats'!B12 -> 2014 | B12: ='Detailed Car List + Stats'!C12 -> Alfa Romeo | C12: ='Detailed Car List + Stats'!D12 -> 4C | D12: ='Detailed Car List + Stats'!E12 -> Modern Sports Cars | E12: A 644 | F12: ='Detailed Car List + Stats'!G12 -> Italy | G12: ='Detailed Car List + Stats'!H12 -> 73000 | H12: Epic | I12: ='Detailed Car List + Stats'!T12 -> Autoshow | J12: ='Detailed Car List + Stats'!U12
A13: ='Detailed Car List + Stats'!B13 -> 2007 | B13: ='Detailed Car List + Stats'!C13 -> Alfa Romeo | C13: ='Detailed Car List + Stats'!D13 -> 8C Competizione | D13: ='Detailed Car List + Stats'!E13 -> GT Cars | E13: A 635 | F13: ='Detailed Car List + Stats'!G13 -> Italy | G13: ='Detailed Car List + Stats'!H13 -> 312000 | H13: Epic | I13: ='Detailed Car List + Stats'!T13 -> Autoshow, Wheelspin | J13: ='Detailed Car List + Stats'!U13
A14: ='Detailed Car List + Stats'!B14 -> 1968 | B14: ='Detailed Car List + Stats'!C14 -> Alfa Romeo | C14: ='Detailed Car List + Stats'!D14 -> Autodelta Tipo 33/2 Daytona | D14: ='Detailed Car List + Stats'!E14 -> Classic Racers | E14: A 696 | F14: ='Detailed Car List + Stats'!G14 -> Italy | G14: ='Detailed Car List + Stats'!H14 | I14: ='Detailed Car List + Stats'!T14 -> Autoshow DLC | J14: ='Detailed Car List + Stats'!U14 -> Car Pass
A15: ='Detailed Car List + Stats'!B15 -> 2021 | B15: ='Detailed Car List + Stats'!C15 -> Alfa Romeo | C15: ='Detailed Car List + Stats'!D15 -> Giulia GTAm | D15: ='Detailed Car List + Stats'!E15 -> Modern Super Saloons | E15: S1 711 | F15: ='Detailed Car List + Stats'!G15 -> Italy | G15: ='Detailed Car List + Stats'!H15 -> 225000 | H15: Rare | I15: ='Detailed Car List + Stats'!T15 -> Autoshow DLC | J15: ='Detailed Car List + Stats'!U15 -> Italian Passion Car Pack
A16: ='Detailed Car List + Stats'!B16 -> 2017 | B16: ='Detailed Car List + Stats'!C16 -> Alfa Romeo | C16: ='Detailed Car List + Stats'!D16 -> Giulia Quadrifoglio | D16: ='Detailed Car List + Stats'!E16 -> Modern Super Saloons | E16: A 667 | F16: ='Detailed Car List + Stats'!G16 -> Italy | G16: ='Detailed Car List + Stats'!H16 -> 45000 | H16: Rare | I16: ='Detailed Car List + Stats'!T16 -> Autoshow, Wheelspin | J16: ='Detailed Car List + Stats'!U16
A17: ='Detailed Car List + Stats'!B17 -> 1965 | B17: ='Detailed Car List + Stats'!C17 -> Alfa Romeo | C17: ='Detailed Car List + Stats'!D17 -> Giulia Sprint GTA Stradale | D17: ='Detailed Car List + Stats'!E17 -> Rare Classics | E17: D 379 | F17: ='Detailed Car List + Stats'!G17 -> Italy | G17: ='Detailed Car List + Stats'!H17 -> 343000 | H17: Rare | I17: ='Detailed Car List + Stats'!T17 -> Autoshow, Wheelspin | J17: ='Detailed Car List + Stats'!U17
A18: ='Detailed Car List + Stats'!B18 -> 1965 | B18: ='Detailed Car List + Stats'!C18 -> Alfa Romeo | C18: ='Detailed Car List + Stats'!D18 -> Giulia TZ2 | D18: ='Detailed Car List + Stats'!E18 -> Classic Racers | E18: B 532 | F18: ='Detailed Car List + Stats'!G18 -> Italy | G18: ='Detailed Car List + Stats'!H18 | I18: ='Detailed Car List + Stats'!T18 -> Collection Journal, Seasonal | J18: ='Detailed Car List + Stats'!U18
A19: ='Detailed Car List + Stats'!B19 -> 1990 | B19: ='Detailed Car List + Stats'!C19 -> Alfa Romeo | C19: ='Detailed Car List + Stats'!D19 -> SE 048SP | D19: ='Detailed Car List + Stats'!E19 -> Retro Racers | E19: R 978 | F19: ='Detailed Car List + Stats'!G19 -> Italy | G19: ='Detailed Car List + Stats'!H19 -> 1000000 | H19: Legendary | I19: ='Detailed Car List + Stats'!T19 -> Autoshow DLC | J19: ='Detailed Car List + Stats'!U19 -> Italian Passion Car Pack
A20: ='Detailed Car List + Stats'!B20 -> 2021 | B20: ='Detailed Car List + Stats'!C20 -> Alumicraft | C20: ='Detailed Car List + Stats'!D20 -> #122 Class 1 Buggy | D20: ='Detailed Car List + Stats'!E20 -> Unlimited Buggies | E20: B 571 | F20: ='Detailed Car List + Stats'!G20 -> USA | G20: ='Detailed Car List + Stats'!H20 -> 160000 | H20: Epic | I20: ='Detailed Car List + Stats'!T20 -> Autoshow, Wheelspin | J20: ='Detailed Car List + Stats'!U20
A21: ='Detailed Car List + Stats'!B21 -> 2022 | B21: ='Detailed Car List + Stats'!C21 -> Alumicraft | C21: ='Detailed Car List + Stats'!D21 -> #6165 Trick Truck | D21: ='Detailed Car List + Stats'!E21 -> Unlimited Offroad | E21: C 485 | F21: ='Detailed Car List + Stats'!G21 -> USA | G21: ='Detailed Car List + Stats'!H21 -> 300000 | H21: Epic | I21: ='Detailed Car List + Stats'!T21 -> Autoshow, Wheelspin | J21: ='Detailed Car List + Stats'!U21
A22: ='Detailed Car List + Stats'!B22 -> 2015 | B22: ='Detailed Car List + Stats'!C22 -> Alumicraft | C22: ='Detailed Car List + Stats'!D22 -> Class 10 Race Car | D22: ='Detailed Car List + Stats'!E22 -> Unlimited Buggies | E22: B 532 | F22: ='Detailed Car List + Stats'!G22 -> USA | G22: ='Detailed Car List + Stats'!H22 -> 45000 | H22: Epic | I22: ='Detailed Car List + Stats'!T22 -> Autoshow, Wheelspin | J22: ='Detailed Car List + Stats'!U22
A23: ='Detailed Car List + Stats'!B23 -> 2554 | B23: ='Detailed Car List + Stats'!C23 -> AMG Transport Dynamics | C23: ='Detailed Car List + Stats'!D23 -> M12S Warthog CST | D23: ='Detailed Car List + Stats'!E23 -> Unlimited Offroad | E23: A 663 | F23: ='Detailed Car List + Stats'!G23 -> USA | G23: ='Detailed Car List + Stats'!H23 -> 850000 | H23: Legendary | I23: ='Detailed Car List + Stats'!T23 -> Autoshow, Collection Journal | J23: ='Detailed Car List + Stats'!U23
A24: ='Detailed Car List + Stats'!B24 -> 2019 | B24: ='Detailed Car List + Stats'!C24 -> Apollo | C24: ='Detailed Car List + Stats'!D24 -> Intensa Emozione | D24: ='Detailed Car List + Stats'!E24 -> Extreme Track Toys | E24: R 916 | F24: ='Detailed Car List + Stats'!G24 -> Germany | G24: ='Detailed Car List + Stats'!H24 | I24: ='Detailed Car List + Stats'!T24 -> Wheelspin, Seasonal | J24: ='Detailed Car List + Stats'!U24
A25: ='Detailed Car List + Stats'!B25 -> 2013 | B25: ='Detailed Car List + Stats'!C25 -> Ariel | C25: ='Detailed Car List + Stats'!D25 -> Atom 500 V8 | D25: ='Detailed Car List + Stats'!E25 -> Extreme Track Toys | E25: S2 825 | F25: ='Detailed Car List + Stats'!G25 -> UK | G25: ='Detailed Car List + Stats'!H25 -> 190000 | H25: Epic | I25: ='Detailed Car List + Stats'!T25 -> Autoshow, Wheelspin | J25: ='Detailed Car List + Stats'!U25
A26: ='Detailed Car List + Stats'!B26 -> 2016 | B26: ='Detailed Car List + Stats'!C26 -> Ariel | C26: ='Detailed Car List + Stats'!D26 -> Nomad | D26: ='Detailed Car List + Stats'!E26 -> Unlimited Buggies | E26: A 601 | F26: ='Detailed Car List + Stats'!G26 -> UK | G26: ='Detailed Car List + Stats'!H26 -> 54000 | H26: Rare | I26: ='Detailed Car List + Stats'!T26 -> Autoshow, Collection Journal, Wheelspin | J26: ='Detailed Car List + Stats'!U26
A27: ='Detailed Car List + Stats'!B27 -> 2017 | B27: ='Detailed Car List + Stats'!C27 -> Aston Martin | C27: ='Detailed Car List + Stats'!D27 -> DB11 | D27: ='Detailed Car List + Stats'!E27 -> Super GT | E27: A 679 | F27: ='Detailed Car List + Stats'!G27 -> UK | G27: ='Detailed Car List + Stats'!H27 -> 175000 | H27: Epic | I27: ='Detailed Car List + Stats'!T27 -> Autoshow, Wheelspin | J27: ='Detailed Car List + Stats'!U27
A28: ='Detailed Car List + Stats'!B28 -> 1964 | B28: ='Detailed Car List + Stats'!C28 -> Aston Martin | C28: ='Detailed Car List + Stats'!D28 -> DB5 | D28: ='Detailed Car List + Stats'!E28 -> Rare Classics | E28: C 416 | F28: ='Detailed Car List + Stats'!G28 -> UK | G28: ='Detailed Car List + Stats'!H28 -> 500000 | H28: Epic | I28: ='Detailed Car List + Stats'!T28 -> Autoshow | J28: ='Detailed Car List + Stats'!U28
A29: ='Detailed Car List + Stats'!B29 -> 2003 | B29: ='Detailed Car List + Stats'!C29 -> Aston Martin | C29: ='Detailed Car List + Stats'!D29 -> DB7 GT | D29: ='Detailed Car List + Stats'!E29 -> Retro Sports Cars | E29: B 566 | F29: ='Detailed Car List + Stats'!G29 -> UK | G29: ='Detailed Car List + Stats'!H29 -> 80000 | H29: Rare | I29: ='Detailed Car List + Stats'!T29 -> Autoshow DLC | J29: ='Detailed Car List + Stats'!U29 -> Car Pass
A30: ='Detailed Car List + Stats'!B30 -> 2019 | B30: ='Detailed Car List + Stats'!C30 -> Aston Martin | C30: ='Detailed Car List + Stats'!D30 -> DBS Superleggera | D30: ='Detailed Car List + Stats'!E30 -> Super GT | E30: S1 736 | F30: ='Detailed Car List + Stats'!G30 -> UK | G30: ='Detailed Car List + Stats'!H30 | I30: ='Detailed Car List + Stats'!T30 -> Wheelspin, Seasonal | J30: ='Detailed Car List + Stats'!U30
A31: ='Detailed Car List + Stats'!B31 -> 2021 | B31: ='Detailed Car List + Stats'!C31 -> Aston Martin | C31: ='Detailed Car List + Stats'!D31 -> DBX | D31: ='Detailed Car List + Stats'!E31 -> Sports Utility Heroes | E31: A 618 | F31: ='Detailed Car List + Stats'!G31 -> UK | G31: ='Detailed Car List + Stats'!H31 -> 250000 | H31: Rare | I31: ='Detailed Car List + Stats'!T31 -> Seasonal | J31: ='Detailed Car List + Stats'!U31
A32: ='Detailed Car List + Stats'!B32 -> 2019 | B32: ='Detailed Car List + Stats'!C32 -> Aston Martin | C32: ='Detailed Car List + Stats'!D32 -> Valhalla Concept Car | D32: ='Detailed Car List + Stats'!E32 -> Hypercars | E32: R 960 | F32: ='Detailed Car List + Stats'!G32 -> UK | G32: ='Detailed Car List + Stats'!H32 | I32: ='Detailed Car List + Stats'!T32 -> Wheelspin, Seasonal | J32: ='Detailed Car List + Stats'!U32
A33: ='Detailed Car List + Stats'!B33 -> 2023 | B33: ='Detailed Car List + Stats'!C33 -> Aston Martin | C33: ='Detailed Car List + Stats'!D33 -> Valkyrie | D33: ='Detailed Car List + Stats'!E33 -> Hypercars | E33: R 924 | F33: ='Detailed Car List + Stats'!G33 -> UK | G33: ='Detailed Car List + Stats'!H33 -> 2750000 | H33: Legendary | I33: ='Detailed Car List + Stats'!T33 -> Autoshow, Wheelspin | J33: ='Detailed Car List + Stats'!U33
A34: ='Detailed Car List + Stats'!B34 -> 2022 | B34: ='Detailed Car List + Stats'!C34 -> Aston Martin | C34: ='Detailed Car List + Stats'!D34 -> Valkyrie AMR Pro | D34: ='Detailed Car List + Stats'!E34 -> Extreme Track Toys | E34: R 989 | F34: ='Detailed Car List + Stats'!G34 -> UK | G34: ='Detailed Car List + Stats'!H34 -> 4200000 | H34: Legendary | I34: ='Detailed Car List + Stats'!T34 -> Autoshow, Collection Journal, Wheelspin | J34: ='Detailed Car List + Stats'!U34
A35: ='Detailed Car List + Stats'!B35 -> 2019 | B35: ='Detailed Car List + Stats'!C35 -> Aston Martin | C35: ='Detailed Car List + Stats'!D35 -> Vantage | D35: ='Detailed Car List + Stats'!E35 -> GT Cars | E35: A 696 | F35: ='Detailed Car List + Stats'!G35 -> UK | G35: ='Detailed Car List + Stats'!H35 -> 250000 | H35: Epic | I35: ='Detailed Car List + Stats'!T35 -> Autoshow | J35: ='Detailed Car List + Stats'!U35
A36: ='Detailed Car List + Stats'!B36 -> 2016 | B36: ='Detailed Car List + Stats'!C36 -> Aston Martin | C36: ='Detailed Car List + Stats'!D36 -> Vulcan | D36: ='Detailed Car List + Stats'!E36 -> Extreme Track Toys | E36: S2 884 | F36: ='Detailed Car List + Stats'!G36 -> UK | G36: ='Detailed Car List + Stats'!H36 -> 2300000 | H36: Legendary | I36: ='Detailed Car List + Stats'!T36 -> Autoshow, Wheelspin, Loyalty | J36: ='Detailed Car List + Stats'!U36
A37: ='Detailed Car List + Stats'!B37 -> 2017 | B37: ='Detailed Car List + Stats'!C37 -> Aston Martin | C37: ='Detailed Car List + Stats'!D37 -> Vulcan AMR Pro | D37: ='Detailed Car List + Stats'!E37 -> Extreme Track Toys | E37: S2 898 | F37: ='Detailed Car List + Stats'!G37 -> UK | G37: ='Detailed Car List + Stats'!H37 -> 3000000 | H37: Legendary | I37: ='Detailed Car List + Stats'!T37 -> Autoshow, Wheelspin | J37: ='Detailed Car List + Stats'!U37
A38: ='Detailed Car List + Stats'!B38 -> 1986 | B38: ='Detailed Car List + Stats'!C38 -> Audi | C38: ='Detailed Car List + Stats'!D38 -> #2 Audi Sport Quattro S1 | D38: ='Detailed Car List + Stats'!E38 -> Rally Monsters | E38: S1 726 | F38: ='Detailed Car List + Stats'!G38 -> Germany | G38: ='Detailed Car List + Stats'!H38 -> 750000 | H38: Legendary | I38: ='Detailed Car List + Stats'!T38 -> Autoshow, Wheelspin | J38: ='Detailed Car List + Stats'!U38
A39: ='Detailed Car List + Stats'!B39 -> 2023 | B39: ='Detailed Car List + Stats'!C39 -> Audi | C39: ='Detailed Car List + Stats'!D39 -> R8 Coupé V10 GT RWD | D39: ='Detailed Car List + Stats'!E39 -> Modern Supercars | E39: S1 769 | F39: ='Detailed Car List + Stats'!G39 -> Germany | G39: ='Detailed Car List + Stats'!H39 -> 250000 | H39: Epic | I39: ='Detailed Car List + Stats'!T39 -> Autoshow DLC | J39: ='Detailed Car List + Stats'!U39 -> Car Pass
A40: ='Detailed Car List + Stats'!B40 -> 2013 | B40: ='Detailed Car List + Stats'!C40 -> Audi | C40: ='Detailed Car List + Stats'!D40 -> R8 Coupé V10 Plus 5.2 FSI Quattro | D40: ='Detailed Car List + Stats'!E40 -> Modern Supercars | E40: A 694 | F40: ='Detailed Car List + Stats'!G40 -> Germany | G40: ='Detailed Car List + Stats'!H40 | I40: ='Detailed Car List + Stats'!T40 -> Collection Journal, Seasonal | J40: ='Detailed Car List + Stats'!U40
...

Sheet Detailed Car List + Stats
A1: Owned? | B1: Year | C1: Make | D1: Model | E1: Type | F1: Class | G1: Country | H1: Value (Cr) | I1: Rarity | J1: Power (HP) | K1: Torque (ft-lbs) | L1: Weight (lbs) | M1: Balance (F) | N1: Displacement (L) | O1: Drivetrain | P1: Engine Pos. | Q1: Pounds Per HP | R1: Balance Penalty | S1: Weight Index | T1: Source | U1: Source Info
A2: FALSE | B2: 2017 | C2: Abarth | D2: 124 Spider | E2: Modern Sports Cars | F2: C 450 | G2: Italy | H2: 250000 | I2: Rare | J2: 165 | K2: 184 | L2: 2477 | M2: 0.54 | N2: 1.37 | O2: Rear | P2: Front | Q2: =L2/J2 -> 15.012121 | R2: =0+((ABS(0.5-M2)*1)) -> 0.04 | S2: =Q2*(R2+1) -> 15.612606 | T2: Seasonal
A3: FALSE | B3: 1968 | C3: Abarth | D3: 595 Esseesse | E3: Cult Cars | F3: D 100 | G3: Italy | H3: 25000 | I3: Common | J3: 28 | K3: 34 | L3: 1257 | M3: 0.42 | N3: 0.59 | O3: Rear | P3: Rear | Q3: =L3/J3 -> 44.892857 | R3: =0+((ABS(0.5-M3)*1)) -> 0.08 | S3: =Q3*(R3+1) -> 48.484286 | T3: Autoshow, Wheelspin
A4: FALSE | B4: 2016 | C4: Abarth | D4: 695 Biposto | E4: Hot Hatch | F4: B 540 | G4: Italy | H4: 250000 | I4: Common | T4: Seasonal
A5: FALSE | B5: 1980 | C5: Abarth | D5: Fiat 131 | E5: Classic Rally | F5: D 399 | G5: Italy | H5: 125000 | I5: Common | J5: 140 | K5: 130 | L5: 2161 | M5: 0.54 | N5: 2 | O5: Rear | P5: Front | Q5: =L5/J5 -> 15.435714 | R5: =0+((ABS(0.5-M5)*1)) -> 0.04 | S5: =Q5*(R5+1) -> 16.053143 | T5: Autoshow, Wheelspin
A6: FALSE | B6: 2023 | C6: Acura | D6: Integra A-Spec | E6: Hot Hatch | F6: C 484 | G6: USA | H6: 36000 | I6: Rare | J6: 200 | K6: 192 | L6: 3073 | M6: 0.6 | N6: 1.5 | O6: Front | P6: Front | Q6: =L6/J6 -> 15.365 | R6: =0+((ABS(0.5-M6)*1)) -> 0.1 | S6: =Q6*(R6+1) -> 16.9015 | T6: Autoshow, Wheelspin
A7: FALSE | B7: 2001 | C7: Acura | D7: Integra Type R | E7: Retro Hot Hatch | F7: C 471 | G7: USA | H7: 65000 | I7: Common | J7: 195 | K7: 130 | L7: 2639 | M7: 0.62 | N7: 1.8 | O7: Front | P7: Front | Q7: =L7/J7 -> 13.533333 | R7: =0+((ABS(0.5-M7)*1)) -> 0.12 | S7: =Q7*(R7+1) -> 15.157333 | T7: Autoshow, Wheelspin
A8: FALSE | B8: 2022 | C8: Acura | D8: NSX Type S | E8: Modern Supercars | F8: S1 734 | G8: USA | H8: 193000 | I8: Epic | T8: Seasonal
A9: FALSE | B9: 2002 | C9: Acura | D9: RSX Type S | E9: Retro Hot Hatch | F9: C 462 | G9: USA | H9: 18000 | I9: Common | J9: 200 | K9: 142 | L9: 2820 | M9: 0.61 | N9: 2 | O9: Front | P9: Front | Q9: =L9/J9 -> 14.1 | R9: =0+((ABS(0.5-M9)*1)) -> 0.11 | S9: =Q9*(R9+1) -> 15.651 | T9: Autoshow, Wheelspin
A10: FALSE | B10: 1992 | C10: Alfa Romeo | D10: 155 Q4 | E10: Retro Super Saloons | F10: C 439 | G10: Italy | H10: 30000 | I10: Epic | J10: 187 | K10: 219 | L10: 3186 | M10: 0.61 | N10: 2 | O10: All | P10: Front | Q10: =L10/J10 -> 17.037433 | R10: =0+((ABS(0.5-M10)*1)) -> 0.11 | S10: =Q10*(R10+1) -> 18.911551 | T10: Autoshow
A11: FALSE | B11: 1968 | C11: Alfa Romeo | D11: 33 Stradale | E11: Classic Racers | F11: B 593 | G11: Italy | H11: 3500000 | I11: Legendary | J11: 245 | K11: 148 | L11: 1543 | M11: 0.4 | N11: 2 | O11: Rear | P11: Mid | Q11: =L11/J11 -> 6.2979592 | R11: =0+((ABS(0.5-M11)*1)) -> 0.1 | S11: =Q11*(R11+1) -> 6.9277551 | T11: Autoshow, Wheelspin
A12: FALSE | B12: 2014 | C12: Alfa Romeo | D12: 4C | E12: Modern Sports Cars | F12: A 644 | G12: Italy | H12: 73000 | I12: Epic | J12: 240 | K12: 238 | L12: 2072 | M12: 0.41 | N12: 1.74 | O12: Rear | P12: Mid | Q12: =L12/J12 -> 8.6333333 | R12: =0+((ABS(0.5-M12)*1)) -> 0.09 | S12: =Q12*(R12+1) -> 9.4103333 | T12: Autoshow
A13: FALSE | B13: 2007 | C13: Alfa Romeo | D13: 8C Competizione | E13: GT Cars | F13: A 635 | G13: Italy | H13: 312000 | I13: Epic | J13: 450 | K13: 354 | L13: 3495 | M13: 0.49 | N13: 4.69 | O13: Rear | P13: Front | Q13: =L13/J13 -> 7.7666667 | R13: =0+((ABS(0.5-M13)*1)) -> 0.01 | S13: =Q13*(R13+1) -> 7.8443333 | T13: Autoshow, Wheelspin
A14: FALSE | B14: 1968 | C14: Alfa Romeo | D14: Autodelta Tipo 33/2 Daytona | E14: Classic Racers | F14: A 696 | G14: Italy | J14: 270 | K14: 160 | L14: 1529 | M14: 0.46 | N14: 2 | O14: Rear | P14: Mid | Q14: =L14/J14 -> 5.662963 | R14: =0+((ABS(0.5-M14)*1)) -> 0.04 | S14: =Q14*(R14+1) -> 5.8894815 | T14: Autoshow DLC | U14: Car Pass
A15: FALSE | B15: 2021 | C15: Alfa Romeo | D15: Giulia GTAm | E15: Modern Super Saloons | F15: S1 711 | G15: Italy | H15: 225000 | I15: Rare | J15: 540 | K15: 442 | L15: 3483 | M15: 0.54 | N15: 2.89 | O15: Rear | P15: Front | Q15: =L15/J15 -> 6.45 | R15: =0+((ABS(0.5-M15)*1)) -> 0.04 | S15: =Q15*(R15+1) -> 6.708 | T15: Autoshow DLC | U15: Italian Passion Car Pack
A16: FALSE | B16: 2017 | C16: Alfa Romeo | D16: Giulia Quadrifoglio | E16: Modern Super Saloons | F16: A 667 | G16: Italy | H16: 45000 | I16: Rare | J16: 506 | K16: 442 | L16: 3749 | M16: 0.5 | N16: 2.89 | O16: Rear | P16: Front | Q16: =L16/J16 -> 7.4090909 | R16: =0+((ABS(0.5-M16)*1)) -> 0 | S16: =Q16*(R16+1) -> 7.4090909 | T16: Autoshow, Wheelspin
A17: FALSE | B17: 1965 | C17: Alfa Romeo | D17: Giulia Sprint GTA Stradale | E17: Rare Classics | F17: D 379 | G17: Italy | H17: 343000 | I17: Rare | J17: 115 | K17: 105 | L17: 1676 | M17: 0.54 | N17: 1.57 | O17: Rear | P17: Front | Q17: =L17/J17 -> 14.573913 | R17: =0+((ABS(0.5-M17)*1)) -> 0.04 | S17: =Q17*(R17+1) -> 15.15687 | T17: Autoshow, Wheelspin
A18: FALSE | B18: 1965 | C18: Alfa Romeo | D18: Giulia TZ2 | E18: Classic Racers | F18: B 532 | G18: Italy | T18: Collection Journal, Seasonal
A19: FALSE | B19: 1990 | C19: Alfa Romeo | D19: SE 048SP | E19: Retro Racers | F19: R 978 | G19: Italy | H19: 1000000 | I19: Legendary | J19: 680 | K19: 320 | L19: 1819 | M19: 0.46 | N19: 3.5 | O19: Rear | P19: Mid | Q19: =L19/J19 -> 2.675 | R19: =0+((ABS(0.5-M19)*1)) -> 0.04 | S19: =Q19*(R19+1) -> 2.782 | T19: Autoshow DLC | U19: Italian Passion Car Pack
A20: FALSE | B20: 2021 | C20: Alumicraft | D20: #122 Class 1 Buggy | E20: Unlimited Buggies | F20: B 571 | G20: USA | H20: 160000 | I20: Epic | J20: 495 | K20: 450 | L20: 3750 | M20: 0.38 | N20: 6.16 | O20: Rear | P20: Rear | Q20: =L20/J20 -> 7.5757576 | R20: =0+((ABS(0.5-M20)*1)) -> 0.12 | S20: =Q20*(R20+1) -> 8.4848485 | T20: Autoshow, Wheelspin
A21: FALSE | B21: 2022 | C21: Alumicraft | D21: #6165 Trick Truck | E21: Unlimited Offroad | F21: C 485 | G21: USA | H21: 300000 | I21: Epic | J21: 430 | K21: 430 | L21: 5750 | M21: 0.47 | N21: 6.16 | O21: Rear | P21: Front | Q21: =L21/J21 -> 13.372093 | R21: =0+((ABS(0.5-M21)*1)) -> 0.03 | S21: =Q21*(R21+1) -> 13.773256 | T21: Autoshow, Wheelspin
A22: FALSE | B22: 2015 | C22: Alumicraft | D22: Class 10 Race Car | E22: Unlimited Buggies | F22: B 532 | G22: USA | H22: 45000 | I22: Epic | J22: 195 | K22: 190 | L22: 2200 | M22: 0.45 | N22: 2.38 | O22: Rear | P22: Rear | Q22: =L22/J22 -> 11.282051 | R22: =0+((ABS(0.5-M22)*1)) -> 0.05 | S22: =Q22*(R22+1) -> 11.846154 | T22: Autoshow, Wheelspin
A23: FALSE | B23: 2554 | C23: AMG Transport Dynamics | D23: M12S Warthog CST | E23: Unlimited Offroad | F23: A 663 | G23: USA | H23: 850000 | I23: Legendary | J23: 965 | K23: 905 | L23: 5071 | M23: 0.54 | N23: 8 | O23: All | P23: Front | Q23: =L23/J23 -> 5.2549223 | R23: =0+((ABS(0.5-M23)*1)) -> 0.04 | S23: =Q23*(R23+1) -> 5.4651192 | T23: Autoshow, Collection Journal
A24: FALSE | B24: 2019 | C24: Apollo | D24: Intensa Emozione | E24: Extreme Track Toys | F24: R 916 | G24: Germany | T24: Wheelspin, Seasonal
A25: FALSE | B25: 2013 | C25: Ariel | D25: Atom 500 V8 | E25: Extreme Track Toys | F25: S2 825 | G25: UK | H25: 190000 | I25: Epic | J25: 475 | K25: 268 | L25: 1433 | M25: 0.36 | N25: 2.97 | O25: Rear | P25: Mid | Q25: =L25/J25 -> 3.0168421 | R25: =0+((ABS(0.5-M25)*1)) -> 0.14 | S25: =Q25*(R25+1) -> 3.4392 | T25: Autoshow, Wheelspin
A26: FALSE | B26: 2016 | C26: Ariel | D26: Nomad | E26: Unlimited Buggies | F26: A 601 | G26: UK | H26: 54000 | I26: Rare | J26: 235 | K26: 221 | L26: 1477 | M26: 0.38 | N26: 2.35 | O26: Rear | P26: Rear | Q26: =L26/J26 -> 6.2851064 | R26: =0+((ABS(0.5-M26)*1)) -> 0.12 | S26: =Q26*(R26+1) -> 7.0393191 | T26: Autoshow, Collection Journal, Wheelspin
A27: FALSE | B27: 2017 | C27: Aston Martin | D27: DB11 | E27: Super GT | F27: A 679 | G27: UK | H27: 175000 | I27: Epic | J27: 608 | K27: 516 | L27: 4134 | M27: 0.51 | N27: 5.2 | O27: Rear | P27: Front | Q27: =L27/J27 -> 6.7993421 | R27: =0+((ABS(0.5-M27)*1)) -> 0.01 | S27: =Q27*(R27+1) -> 6.8673355 | T27: Autoshow, Wheelspin
A28: FALSE | B28: 1964 | C28: Aston Martin | D28: DB5 | E28: Rare Classics | F28: C 416 | G28: UK | H28: 500000 | I28: Epic | J28: 282 | K28: 282 | L28: 3230 | M28: 0.51 | N28: 4 | O28: Rear | P28: Front | Q28: =L28/J28 -> 11.453901 | R28: =0+((ABS(0.5-M28)*1)) -> 0.01 | S28: =Q28*(R28+1) -> 11.56844 | T28: Autoshow
A29: FALSE | B29: 2003 | C29: Aston Martin | D29: DB7 GT | E29: Retro Sports Cars | F29: B 566 | G29: UK | H29: 80000 | I29: Rare | J29: 435 | K29: 410 | L29: 3968 | M29: 0.55 | N29: 5.94 | O29: Rear | P29: Front | Q29: =L29/J29 -> 9.1218391 | R29: =0+((ABS(0.5-M29)*1)) -> 0.05 | S29: =Q29*(R29+1) -> 9.577931 | T29: Autoshow DLC | U29: Car Pass
A30: FALSE | B30: 2019 | C30: Aston Martin | D30: DBS Superleggera | E30: Super GT | F30: S1 736 | G30: UK | T30: Wheelspin, Seasonal
A31: FALSE | B31: 2021 | C31: Aston Martin | D31: DBX | E31: Sports Utility Heroes | F31: A 618 | G31: UK | H31: 250000 | I31: Rare | T31: Seasonal
A32: FALSE | B32: 2019 | C32: Aston Martin | D32: Valhalla Concept Car | E32: Hypercars | F32: R 960 | G32: UK | T32: Wheelspin, Seasonal
A33: FALSE | B33: 2023 | C33: Aston Martin | D33: Valkyrie | E33: Hypercars | F33: R 924 | G33: UK | H33: 2750000 | I33: Legendary | J33: 1140 | K33: 663 | L33: 2976 | M33: 0.4 | N33: 6.5 | O33: Rear | P33: Mid | Q33: =L33/J33 -> 2.6105263 | R33: =0+((ABS(0.5-M33)*1)) -> 0.1 | S33: =Q33*(R33+1) -> 2.8715789 | T33: Autoshow, Wheelspin
A34: FALSE | B34: 2022 | C34: Aston Martin | D34: Valkyrie AMR Pro | E34: Extreme Track Toys | F34: R 989 | G34: UK | H34: 4200000 | I34: Legendary | J34: 1000 | K34: 545 | L34: 2370 | M34: 0.42 | N34: 6.5 | O34: Rear | P34: Mid | Q34: =L34/J34 -> 2.37 | R34: =0+((ABS(0.5-M34)*1)) -> 0.08 | S34: =Q34*(R34+1) -> 2.5596 | T34: Autoshow, Collection Journal, Wheelspin
A35: FALSE | B35: 2019 | C35: Aston Martin | D35: Vantage | E35: GT Cars | F35: A 696 | G35: UK | H35: 250000 | I35: Epic | J35: 503 | K35: 505 | L35: 3497 | M35: 0.5 | N35: 3.98 | O35: Rear | P35: Front | Q35: =L35/J35 -> 6.9522863 | R35: =0+((ABS(0.5-M35)*1)) -> 0 | S35: =Q35*(R35+1) -> 6.9522863 | T35: Autoshow
A36: FALSE | B36: 2016 | C36: Aston Martin | D36: Vulcan | E36: Extreme Track Toys | F36: S2 884 | G36: UK | H36: 2300000 | I36: Legendary | J36: 820 | K36: 590 | L36: 2998 | M36: 0.54 | N36: 6.95 | O36: Rear | P36: Front | Q36: =L36/J36 -> 3.6560976 | R36: =0+((ABS(0.5-M36)*1)) -> 0.04 | S36: =Q36*(R36+1) -> 3.8023415 | T36: Autoshow, Wheelspin, Loyalty
A37: FALSE | B37: 2017 | C37: Aston Martin | D37: Vulcan AMR Pro | E37: Extreme Track Toys | F37: S2 898 | G37: UK | H37: 3000000 | I37: Legendary | J37: 820 | K37: 590 | L37: 2998 | M37: 0.54 | N37: 6.95 | O37: Rear | P37: Front | Q37: =L37/J37 -> 3.6560976 | R37: =0+((ABS(0.5-M37)*1)) -> 0.04 | S37: =Q37*(R37+1) -> 3.8023415 | T37: Autoshow, Wheelspin
A38: FALSE | B38: 1986 | C38: Audi | D38: #2 Audi Sport Quattro S1 | E38: Rally Monsters | F38: S1 726 | G38: Germany | H38: 750000 | I38: Legendary | J38: 469 | K38: 354 | L38: 2403 | M38: 0.52 | N38: 2.11 | O38: All | P38: Front | Q38: =L38/J38 -> 5.1236674 | R38: =0+((ABS(0.5-M38)*1)) -> 0.02 | S38: =Q38*(R38+1) -> 5.2261407 | T38: Autoshow, Wheelspin
A39: FALSE | B39: 2023 | C39: Audi | D39: R8 Coupé V10 GT RWD | E39: Modern Supercars | F39: S1 769 | G39: Germany | H39: 250000 | I39: Epic | J39: 611 | K39: 416 | L39: 3516 | M39: 0.4 | N39: 5.2 | O39: Rear | P39: Mid | Q39: =L39/J39 -> 5.7545008 | R39: =0+((ABS(0.5-M39)*1)) -> 0.1 | S39: =Q39*(R39+1) -> 6.3299509 | T39: Autoshow DLC | U39: Car Pass
A40: FALSE | B40: 2013 | C40: Audi | D40: R8 Coupé V10 Plus 5.2 FSI Quattro | E40: Modern Supercars | F40: A 694 | G40: Germany | T40: Collection Journal, Seasonal
...
